Workbook

Sheet 1. Assumptions 
B3: LIST OF ASSUMPTION USED IN THE MODEL
B4: Assumption | D4: Reasons | Q4: Economic Net Worth | R4: Total Pension Value | S4: Total Human Capital Value
B5: Salary | C5: Huyen: Bank Teller. Huyen's husband: Recruitment Assistant. We will not change the career path. | D5: Huyen works in the financial industry.
B6: Mortgage and saving rate | C6: The applicable rates will remain stable. | D6: The applicable rates are the average of 13 banks in Vietnam. | G6: Total Pension Value | J6: ='[1]3'!I19 -> #REF!
B7: Inflation | C7: Annual living expenses increase with inflation rate. | D7: We do not change our lifestyle. | G7: Total Human Capital Value | J7: ='[1]3'!I16 -> #REF!
B8: Annual salary growth rate | C8: Using inflation rate as annual salary growth rate. | D8: We will not change the career path.
B9: Risk-Free rate | C9: Vietnam 30 year bond yield is fixed through the calculated period. | D9: Vietnam's 30 year bond yield serves as the risk-free rate.
B10: Retirement age | C10: Huyen and Huyen's husband retire, regulated by a new law. Specifically, Huyen retires at 60 and Huyen's husband retires at 62. Both retire at the end of the year. | D10: Based on Decree 135/2020 ND-CP.
B11: Marriage | C11: We marry at the end of year 2025 at all parent cost, wedding money will be a part of our saving cost. | D11: Our parents will support our wedding.
B12: Insurance premiums | C12: Insurance premiums are fixed during the contract period. | D12: Most insurance contracts promise fixed premiums.
B13: Life insurance | C13: We buy life insurance when we turn 30 years old. | D13: We hedge against premature death risk during the working period.
B14: Child | C14: Our child will become independent when he turns 22 years old. | D14: He can take responsibility for his life.
B15: Travel | C15: Travel in Asia, Europe, Australia and Africa. | D15: We fulfill our dream to travel around the world.
B16: Life expectancy | C16: Both will die at the end of the year 2088. | D16: Our life expectancy is both 85 years old.
B18: Key Financial Data | C18: Link
B19: Huyen's salary | C19: https://vtcnews.vn/soi-muc-luong-pho-bien-cua-cac-vi-tri-trong-ngan-hang-ar808150.html
B20: Huyen's husband salary | C20: https://vinatrain.edu.vn/muc-luong-cua-nhan-vien-tuyen-dung/
B21: Mortgage Interest Rate | C21: https://www.vpbank.com.vn/bi-kip-va-chia-se/retail-story-and-tips/loans-category/lai-suat-vay-mua-nha
B22: Bank Deposit Rate | C22: https://vietnamnet.vn/lai-suat-ngan-hang-hom-nay-14-5-2025-ky-han-6-thang-lai-suat-cao-nhat-5-65-2400896.html
B23: Inflation | C23: Vietnam- inflation rate 2029 | Statista
B24: Risk-Free Rate | C24: Vietnam 30 Year Bond Yield - Investing.com
B25: Tax Deduction And Duty | C25: https://thuvienphapluat.vn/van-ban/Thue-Phi-Le-Phi/Luat-thue-thu-nhap-ca-nhan-2007-04-2007-QH12-59652.aspx
B26: Tax | C26: Cách tính mức lương đóng BHXH 2024 từ 01/7 khi tăng lương tối thiểu vùng? Công thức tính lương đóng bảo hiểm xã hội mới nhất hiện nay thế nào? (thuvienphapluat.vn)
B27: Pension Value | C27: https://thuvienphapluat.vn/van-ban/Bao-hiem/Nghi-dinh-115-2015-ND-CP-huong-dan-Luat-bao-hiem-xa-hoi-bat-buoc-279974.aspx?anchor=dieu_9
B28: Probility Of Death | C28: Life tables: Life tables by country Viet Nam
B29: Retirement Age | C29: https://thuvienphapluat.vn/van-ban/Lao-dong-Tien-luong/Nghi-dinh-135-2020-ND-CP-tuoi-nghi-huu-445512.aspx
... B36: Car model | C36: https://toyota-angiang5s.com/san-pham/toyota-vios/

Sheet 2. Financial goals 
B3: Personal Image
B4: Age | C4: 22
B5: Married status | C5: Single
B6: Occupation | C6: Bank teller
B7: Accommodation | C7: Renting a one-bedroom apartment
B8: Source of income | C8: Salary from employment
B9: Career Timline | C9: Planning to work until retirement
B10: Life expectancy | C10: 85 years
B14: Period | D14: Position | E14: Goal | F14: Link
B15: Establishing a strong financial foundation (22-26) | C15: 22 - 24 | D15: Bank teller | E15: Get married and start a family. Focus on building my career and gaining valuable knowledge, start saving
C16: 25-26 | D16: Promotion to Controller | E16: Achieve a promotion and ensure financial stability to cover all expenses.
B17: Strategic Wealth Growth and Accumulation (27-60) | C17: 27-30 | D17: Promotion to Deputy Head of Customer Service | E17: Give birth child
C18: 31-33 | D18: Promotion to Head of Customer Service | E18: Purchase house worth VND 2 billion 450.
C19: 34-36 | D19: Promotion to Deputy Director of Operations | E19: In process of paying mortgage debt.
C20: 37-60 | D20: Promotion to Branch Director | E20: Pay off mortgage debt. Buy car worth VND 500 million.
B21: Sustaining and Optimizing Wealth Distribution (61-85) | C21: 61-85 | D21: Retirement | E21: Enjoy a secure, worry-free retirement and travel around the world.
B22: FOR RISK MANAGEMENT
B23: Earning risk | C23: Protect earning and human capital. | D23: Pay social insurance and save frequently.
B24: Health risk | C24: Minimize large medical expenses for the family. | D24: Buy health insurance for the family.
B25: Premature death risk | C25: Protect source of income for the family. | D25: Buy life insurance for both breadwinners.
B26: FOR CAPITAL ACCUMULATION
B27: Emergency fund | C27: Cover shorfall in income to ensure the minimum living standard.
B28: Savings fund | C28: Have savings fund by adding surplus left at the end of each period to next year saving amount.
B29: Investment fund | C29: Invest in stock and bond fund to earn interest and ensure cash inflow.

Sheet 3. Financial drivers 
B2: Taxable Income | F2: Applicable Interest Rate for Mortgage in 2025 | I2: Link | J2: Applicable Interest Rate for Deposit in 12 months | M2: Link
B3: Tax grade | C3: Taxable income/year (VND million) | D3: Tax rate | E3: Link | F3: No | G3: Bank's Name | H3: Applicable Interest Rate | J3: No | K3: Bank's Name | L3: Applicable Interest Rate
B4: 1 | C4: Up to 60 | D4: 0.05 | F4: 1 | G4: BIDV | H4: 0.05 | J4: 1 | K4: BIDV | L4: 0.047
B5: 2 | C5: Between over 60 and 120 | D5: 0.1 | F5: =F4+1 -> 2 | G5: Vietcombank | H5: 0.055 | J5: =J4+1 -> 2 | K5: Vietcombank | L5: 0.046
B6: 3 | C6: Between over 120 and 216 | D6: 0.15 | F6: =F5+1 -> 3 | G6: Agribank | H6: 0.06 | J6: =J5+1 -> 3 | K6: Agribank | L6: 0.048
B7: 4 | C7: Between over 216 and 384 | D7: 0.2 | F7: =F6+1 -> 4 | G7: Vietinbank | H7: 0.06 | J7: =J6+1 -> 4 | K7: Vietinbank | L7: 0.047
B8: 5 | C8: Between over 384 and 624 | D8: 0.25 | F8: =F7+1 -> 5 | G8: VIB | H8: 0.065 | J8: =J7+1 -> 5 | K8: VIB | L8: 0.049
B9: 6 | C9: Between over 624 and 960 | D9: 0.3 | F9: =F8+1 -> 6 | G9: Techcombank | H9: 0.067 | J9: =J8+1 -> 6 | K9: Techcombank | L9: 0.0475
B10: 7 | C10: Over 960 | D10: 0.35 | F10: =F9+1 -> 7 | G10: VPBank | H10: 0.072 | J10: =J9+1 -> 7 | K10: VPBank | L10: 0.05
F11: =F10+1 -> 8 | G11: TPBank | H11: 0.066 | J11: =J10+1 -> 8 | K11: TPBank | L11: 0.052
B12: Tax Deduction | D12: VND/year | F12: =F11+1 -> 9 | G12: ACB | H12: 0.07 | J12: =J11+1 -> 9 | K12: ACB | L12: 0.049
B13: Personal exemption | D13: 132000000 | E13: Link | F13: =F12+1 -> 10 | G13: Sacombank | H13: 0.07 | J13: =J12+1 -> 10 | K13: Sacombank | L13: 0.054
B14: Dependent exemption/ per dependent | D14: =4400000*12 -> 52800000 | E14: Link | F14: =F13+1 -> 11 | G14: MSB | H14: 0.062 | J14: =J13+1 -> 11 | K14: MSB | L14: 0.056
F15: =F14+1 -> 12 | G15: HDBank | H15: 0.065 | J15: =J14+1 -> 12 | K15: HDBank | L15: 0.056
F16: =F15+1 -> 13 | G16: MBBank | H16: 0.079 | J16: =J15+1 -> 13 | K16: MBBank | L16: 0.05
B17: Remaining Car Value | E17: Link | F17: Average | H17: =AVERAGE(H4:H16) -> 0.064692308 | J17: Average | L17: =MAX(L4:L16) -> 0.056
B18: Recently bought | D18: 1
B19: Within 1 year after buying | D19: 0.9
B20: Within over 1 year and 3 years after buying | D20: 0.7 | F20: Inflation Rate | H20: Link | J20: Calculations Of Discount Rate For Human Capital
B21: Within over 3 years and 6 years after buying | D21: 0.5 | F21: Year | G21: Rate | J21: Risk Free Rate (Vietnam Government Bond 20Y) | L21: 0.03474 | M21: Link
B22: Within over 6 years and 10 years after buying | D22: 0.3 | F22: 2021 | G22: 0.0184 | J22: Risk Premium Relating to Huyen's income | L22: 0.035
B23: Over 10 years after buying | D23: 0.2 | F23: =F22+1 -> 2022 | G23: 0.0316 | J23: Risk Premium Relating to Huyen's husband ncome | L23: 0.035
F24: =F23+1 -> 2023 | G24: 0.0325 | J24: Discount Rate For Huyen's income | L24: =L22+L21 -> 0.06974
B25: Huyen's Car Model | E25: Link | F25: =F24+1 -> 2024 | G25: 0.0362 | J25: Discount Rate For Huyen's husband income | L25: =L23+L21 -> 0.06974
B26: Huyen's Car | D26: VIOS 1.5E-MT | F26: =F25+1 -> 2025 | G26: 0.0295
B27: Buying price (in 2035) | D27: 458000000 | F27: =F26+1 -> 2026 | G27: 0.0249
F28: =F27+1 -> 2027 | G28: 0.028
F29: =F28+1 -> 2028 | G29: 0.029
F30: =F29+1 -> 2029 | G30: 0.029
F31: =F30+1 -> 2030 | G31: 0.029
F32: 2030 Afterwards | G32: =AVERAGE(G22:G31) -> 0.02881

Sheet 4. Balance sheet 
B2: Traditional Balance Sheet at the end of 2025, unit VND | K2: Economic Balance Sheet, unit VND
B4: ASSETS | C4: VND | D4: % | F4: LIABILITIES | G4: VND | H4: % | K4: ASSETS | L4: VND | M4: % | O4: LIABILITIES | P4: VND | Q4: %
B5: Liquid Assets | F5: Liabilities | K5: Assets | O5: Liabilities
B6: Cash | C6: 10000000 | D6: =C6/$C$18 -> 0.033757553 | F6: Short-term Liabilities | G6: 0 | H6: 0 | K6: Liquid Assets | O6: Short-term Liabilities | P6: 0 | Q6: 0
B7: Saving Account | C7: 70000000 | D7: =C7/$C$18 -> 0.23630287 | F7: Long-term Liabilities | G7: 0 | H7: 0 | K7: Cash | L7: 10000000 | M7: =L7/$L$25 -> 0.00055795519 | O7: Long-term Liabilities | P7: 0 | Q7: 0
B8: Checking Account | C8: 20000000 | D8: =C8/$C$18 -> 0.067515107 | F8: Others | G8: 0 | H8: 0 | K8: Saving Account | L8: 70000000 | M8: =L8/$L$25 -> 0.0039056864 | O8: Others | P8: 0 | Q8: 0
B9: Total liquid assets | C9: =SUM(C6:C8) -> 100000000 | D9: =C9/$C$18 -> 0.33757553 | F9: TOTAL LIABILITIES | G9: =SUM(G6:G8) -> 0 | K9: Checking Account | L9: 20000000 | M9: =L9/$L$25 -> 0.0011159104 | O9: Present Value of Lifetime Consumption Needs | P9: ='7. Human capital & pension valu'!C59 -> 3.0672922e+10
B10: Tangible Assets | F10: Net Worth | G10: =C18-G9 -> 296230000 | K10: Total liquid assets | L10: =SUM(L7:L9) -> 100000000 | O10: Economic Net Worth | P10: =L25-P9 -> -1.2750335e+10
B11: iPhone 15 promax | C11: 25000000 | D11: =C11/$C$18 -> 0.084393883 | F11: TOTAL LIABILITIES & NET WORTH | G11: =G10+G9 -> 296230000 | K11: Tangible Assets
B12: iPhone 16 promax | C12: 27990000 | D12: =C12/$C$18 -> 0.094487392 | K12: iPhone 15 promax | L12: 25000000 | M12: =L12/$L$25 -> 0.001394888
B13: Macbook Air 2017 | C13: 25000000 | D13: =C13/$C$18 -> 0.084393883 | K13: iPhone 16 promax | L13: 27990000 | M13: =L13/$L$25 -> 0.0015617166
B14: iPad | C14: 18000000 | D14: =C14/$C$18 -> 0.060763596 | F14: Short-term Liabilities | K14: Macbook Air 2017 | L14: 25000000 | M14: =L14/$L$25 -> 0.001394888
B15: Honda Scoopy | C15: 56000000 | D15: =C15/$C$18 -> 0.1890423 | K15: iPad | L15: 18000000 | M15: =L15/$L$25 -> 0.0010043194
B16: AirBlade 160 | C16: 44240000 | D16: =C16/$C$18 -> 0.14934342 | K16: Honda Scoopy | L16: 56000000 | M16: =L16/$L$25 -> 0.0031245491
B17: Total tangible assets | C17: =SUM(C11:C16) -> 196230000 | D17: =C17/$C$18 -> 0.66242447 | F17: Long-term Liabilities | G17: =G7 -> 0 | K17: AirBlade 160 | L17: 44240000 | M17: =L17/$L$25 -> 0.0024683938
B18: TOTAL ASSETS | C18: =C9+C17 -> 296230000 | K18: Total tangible assets | L18: =SUM(L12:L17) -> 196230000
K19: Human Capital
K20: Huyen's Human Capital | L20: ='7. Human capital & pension valu'!C21 -> 6.0981099e+09 | M20: =L20/$L$25 -> 0.34024721
B21: Key Ratio | C21: Formula | D21: Calculation | K21: Huyen's husband Human Capital | L21: ='7. Human capital & pension valu'!C34 -> 6.9863372e+09 | M21: =L21/$L$25 -> 0.38980632
B22: Solvency Ratio | C22: Net Worth/Total assets | D22: =G10/C18 -> 1 | K22: Pension Value
K23: Huyen's Pension Value | L23: ='7. Human capital & pension valu'!AP45 -> 2.2998207e+09 | M23: =L23/$L$25 -> 0.12831969
K24: Huyen's husband Pension Value | L24: ='7. Human capital & pension valu'!AP53 -> 2.2420883e+09 | M24: =L24/$L$25 -> 0.12509848
K25: TOTAL ASSETS | L25: =L10+L18+SUM(L20:L24) -> 1.7922586e+10

Sheet 5. Cash Flow
B2: Cash Flow Statement for the family at the end of 2025 | F2: Financial ratios | G2: Formula | H2: Calculation
B3: Income | C3: VND | D3: % | F3: Saving ratio | G3: Cash surplus/ income after tax | H3: =C11/('7. Human capital & pension valu'!C17+'7. Human capital & pension valu'!C30) -> 0.011603749
B4: Huyen's gross salary | C4: ='7. Human capital & pension valu'!C12 -> 179400000 | D4: =C4/C7 -> 0.47420173
B5: Huyen's husband gross salary | C5: ='7. Human capital & pension valu'!C25 -> 195000000 | D5: =C5/C7 -> 0.51543667
B6: Interest | C6: ='8. Budget Estimate'!C13 -> 3920000 | D6: =C6/C7 -> 0.010361599
B7: TOTAL INCOME | C7: =SUM(C4:C6) -> 378320000
B8: Expenses
B9: Living expense | C9: ='8. Budget Estimate'!C39 -> 374388000 | D9: =C9/C10 -> 1
B10: TOTAL EXPENSE | C10: =C9 -> 374388000
B11: Surplus/Deficit | C11: =C7-C10 -> 3932000

Sheet 6. Salary
B3: HUYEN | I3: HUYEN'S HUSBAND
B4: Year | C4: Age | D4: Position | E4: Monthly Salary | F4: Yearly Bonus | G4: Monthly Income | I4: Year | J4: Age | K4: Position | L4: Monthly Salary | M4: Yearly Bonus | N4: Monthly Income
B5: 2025 | C5: 22 | D5: Bank Teller | E5: 13800000 | F5: =E5 -> 13800000 | G5: =E5+F5/12 -> 14950000 | H5: Link | I5: 2025 | J5: 22 | K5: Recruitment Assistant | L5: 15000000 | M5: =L5 -> 15000000 | N5: =L5+M5/12 -> 16250000 | O5: Link
B6: =B5+1 -> 2026 | C6: =C5+1 -> 23 | E6: 13800000 | F6: =E6 -> 13800000 | G6: =E6+F6/12 -> 14950000 | H6: Link | I6: =I5+1 -> 2026 | J6: =J5+1 -> 23 | L6: 15000000 | M6: =L6 -> 15000000 | N6: =L6+M6/12 -> 16250000 | O6: Link
B7: =B6+1 -> 2027 | C7: =C6+1 -> 24 | E7: 13800000 | F7: =E7 -> 13800000 | G7: =E7+F7/12 -> 14950000 | H7: Link | I7: =I6+1 -> 2027 | J7: =J6+1 -> 24 | L7: 15000000 | M7: =L7 -> 15000000 | N7: =L7+M7/12 -> 16250000
B8: =B7+1 -> 2028 | C8: =C7+1 -> 25 | D8: Controller | E8: 17600000 | F8: =E8 -> 17600000 | G8: =E8+F8/12 -> 19066667 | I8: =I7+1 -> 2028 | J8: =J7+1 -> 25 | K8: Recruitment Specialist | L8: 20000000 | M8: =L8 -> 20000000 | N8: =L8+M8/12 -> 21666667
B9: =B8+1 -> 2029 | C9: =C8+1 -> 26 | E9: 17600000 | F9: =E9 -> 17600000 | G9: =E9+F9/12 -> 19066667 | I9: =I8+1 -> 2029 | J9: =J8+1 -> 26 | L9: 20000000 | M9: =L9 -> 20000000 | N9: =L9+M9/12 -> 21666667
B10: =B9+1 -> 2030 | C10: =C9+1 -> 27 | D10: Deputy Head of Customer Service | E10: 20000000 | F10: =E10 -> 20000000 | G10: =E10+F10/12 -> 21666667 | I10: =I9+1 -> 2030 | J10: =J9+1 -> 27 | L10: 20000000 | M10: =L10 -> 20000000 | N10: =L10+M10/12 -> 21666667
B11: =B10+1 -> 2031 | C11: =C10+1 -> 28 | E11: 20000000 | F11: =E11 -> 20000000 | G11: =E11+F11/12 -> 21666667 | I11: =I10+1 -> 2031 | J11: =J10+1 -> 28 | K11: Recruitment Team Leader | L11: 25000000 | M11: =L11 -> 25000000 | N11: =L11+M11/12 -> 27083333
B12: =B11+1 -> 2032 | C12: =C11+1 -> 29 | E12: 20000000 | F12: =E12 -> 20000000 | G12: =E12+F12/12 -> 21666667 | I12: =I11+1 -> 2032 | J12: =J11+1 -> 29 | L12: 25000000 | M12: =L12 -> 25000000 | N12: =L12+M12/12 -> 27083333
B13: =B12+1 -> 2033 | C13: =C12+1 -> 30 | E13: 20000000 | F13: =E13 -> 20000000 | G13: =E13+F13/12 -> 21666667 | I13: =I12+1 -> 2033 | J13: =J12+1 -> 30 | K13: Recruitment Manager | L13: 35000000 | M13: =L13 -> 35000000 | N13: =L13+M13/12 -> 37916667
B14: =B13+1 -> 2034 | C14: =C13+1 -> 31 | D14: Head of Customer Service | E14: 25000000 | F14: =E14 -> 25000000 | G14: =E14+F14/12 -> 27083333 | I14: =I13+1 -> 2034 | J14: =J13+1 -> 31 | L14: 35000000 | M14: =L14 -> 35000000 | N14: =L14+M14/12 -> 37916667
B15: =B14+1 -> 2035 | C15: =C14+1 -> 32 | E15: 25000000 | F15: =E15 -> 25000000 | G15: =E15+F15/12 -> 27083333 | I15: =I14+1 -> 2035 | J15: =J14+1 -> 32 | L15: 35000000 | M15: =L15 -> 35000000 | N15: =L15+M15/12 -> 37916667
B16: =B15+1 -> 2036 | C16: =C15+1 -> 33 | E16: 25000000 | F16: =E16 -> 25000000 | G16: =E16+F16/12 -> 27083333 | I16: =I15+1 -> 2036 | J16: =J15+1 -> 33 | L16: 35000000 | M16: =L16 -> 35000000 | N16: =L16+M16/12 -> 37916667
B17: =B16+1 -> 2037 | C17: =C16+1 -> 34 | D17: Deputy Director of Operations | E17: 40000000 | F17: =E17 -> 40000000 | G17: =E17+F17/12 -> 43333333 | I17: =I16+1 -> 2037 | J17: =J16+1 -> 34 | L17: 35000000 | M17: =L17 -> 35000000 | N17: =L17+M17/12 -> 37916667
B18: =B17+1 -> 2038 | C18: =C17+1 -> 35 | E18: 40000000 | F18: =E18 -> 40000000 | G18: =E18+F18/12 -> 43333333 | I18: =I17+1 -> 2038 | J18: =J17+1 -> 35 | K18: Recruitment Director | L18: 45000000 | M18: =L18 -> 45000000 | N18: =L18+M18/12 -> 48750000
B19: =B18+1 -> 2039 | C19: =C18+1 -> 36 | E19: 40000000 | F19: =E19 -> 40000000 | G19: =E19+F19/12 -> 43333333 | I19: =I18+1 -> 2039 | J19: =J18+1 -> 36 | L19: 45000000 | M19: =L19 -> 45000000 | N19: =L19+M19/12 -> 48750000
B20: =B19+1 -> 2040 | C20: =C19+1 -> 37 | D20: Branch manager | E20: 70000000 | F20: =E20 -> 70000000 | G20: =E20+F20/12 -> 75833333 | I20: =I19+1 -> 2040 | J20: =J19+1 -> 37 | L20: 45000000 | M20: =L20 -> 45000000 | N20: =L20+M20/12 -> 48750000
B21: =B20+1 -> 2041 | C21: =C20+1 -> 38 | E21: 70000000 | F21: =E21 -> 70000000 | G21: =E21+F21/12 -> 75833333 | I21: =I20+1 -> 2041 | J21: =J20+1 -> 38 | L21: 45000000 | M21: =L21 -> 45000000 | N21: =L21+M21/12 -> 48750000
B22: =B21+1 -> 2042 | C22: =C21+1 -> 39 | E22: 70000000 | F22: =E22 -> 70000000 | G22: =E22+F22/12 -> 75833333 | I22: =I21+1 -> 2042 | J22: =J21+1 -> 39 | K22: HR Director | L22: 80000000 | M22: =L22 -> 80000000 | N22: =L22+M22/12 -> 86666667
B23: =B22+1 -> 2043 | C23: =C22+1 -> 40 | E23: 70000000 | F23: =E23 -> 70000000 | G23: =E23+F23/12 -> 75833333 | I23: =I22+1 -> 2043 | J23: =J22+1 -> 40 | L23: 80000000 | M23: =L23 -> 80000000 | N23: =L23+M23/12 -> 86666667
B24: =B23+1 -> 2044 | C24: =C23+1 -> 41 | E24: 70000000 | F24: =E24 -> 70000000 | G24: =E24+F24/12 -> 75833333 | I24: =I23+1 -> 2044 | J24: =J23+1 -> 41 | L24: 80000000 | M24: =L24 -> 80000000 | N24: =L24+M24/12 -> 86666667
B25: =B24+1 -> 2045 | C25: =C24+1 -> 42 | E25: 70000000 | F25: =E25 -> 70000000 | G25: =E25+F25/12 -> 75833333 | I25: =I24+1 -> 2045 | J25: =J24+1 -> 42 | L25: 80000000 | M25: =L25 -> 80000000 | N25: =L25+M25/12 -> 86666667
B26: =B25+1 -> 2046 | C26: =C25+1 -> 43 | E26: 70000000 | F26: =E26 -> 70000000 | G26: =E26+F26/12 -> 75833333 | I26: =I25+1 -> 2046 | J26: =J25+1 -> 43 | L26: 80000000 | M26: =L26 -> 80000000 | N26: =L26+M26/12 -> 86666667
B27: =B26+1 -> 2047 | C27: =C26+1 -> 44 | E27: 70000000 | F27: =E27 -> 70000000 | G27: =E27+F27/12 -> 75833333 | I27: =I26+1 -> 2047 | J27: =J26+1 -> 44 | L27: 80000000 | M27: =L27 -> 80000000 | N27: =L27+M27/12 -> 86666667
B28: =B27+1 -> 2048 | C28: =C27+1 -> 45 | E28: 70000000 | F28: =E28 -> 70000000 | G28: =E28+F28/12 -> 75833333 | I28: =I27+1 -> 2048 | J28: =J27+1 -> 45 | L28: 80000000 | M28: =L28 -> 80000000 | N28: =L28+M28/12 -> 86666667
B29: =B28+1 -> 2049 | C29: =C28+1 -> 46 | E29: 70000000 | F29: =E29 -> 70000000 | G29: =E29+F29/12 -> 75833333 | I29: =I28+1 -> 2049 | J29: =J28+1 -> 46 | L29: 80000000 | M29: =L29 -> 80000000 | N29: =L29+M29/12 -> 86666667
B30: =B29+1 -> 2050 | C30: =C29+1 -> 47 | E30: 70000000 | F30: =E30 -> 70000000 | G30: =E30+F30/12 -> 75833333 | I30: =I29+1 -> 2050 | J30: =J29+1 -> 47 | L30: 80000000 | M30: =L30 -> 80000000 | N30: =L30+M30/12 -> 86666667
B31: =B30+1 -> 2051 | C31: =C30+1 -> 48 | E31: 70000000 | F31: =E31 -> 70000000 | G31: =E31+F31/12 -> 75833333 | I31: =I30+1 -> 2051 | J31: =J30+1 -> 48 | L31: 80000000 | M31: =L31 -> 80000000 | N31: =L31+M31/12 -> 86666667
B32: =B31+1 -> 2052 | C32: =C31+1 -> 49 | E32: 70000000 | F32: =E32 -> 70000000 | G32: =E32+F32/12 -> 75833333 | I32: =I31+1 -> 2052 | J32: =J31+1 -> 49 | L32: 80000000 | M32: =L32 -> 80000000 | N32: =L32+M32/12 -> 86666667
B33: =B32+1 -> 2053 | C33: =C32+1 -> 50 | E33: 70000000 | F33: =E33 -> 70000000 | G33: =E33+F33/12 -> 75833333 | I33: =I32+1 -> 2053 | J33: =J32+1 -> 50 | L33: 80000000 | M33: =L33 -> 80000000 | N33: =L33+M33/12 -> 86666667
B34: =B33+1 -> 2054 | C34: =C33+1 -> 51 | E34: 70000000 | F34: =E34 -> 70000000 | G34: =E34+F34/12 -> 75833333 | I34: =I33+1 -> 2054 | J34: =J33+1 -> 51 | L34: 80000000 | M34: =L34 -> 80000000 | N34: =L34+M34/12 -> 86666667
... B43: =B42+1 -> 2063 | C43: =C42+1 -> 60 | E43: 70000000 | F43: =E43 -> 70000000 | G43: =E43+F43/12 -> 75833333 | I43: =I42+1 -> 2063 | J43: =J42+1 -> 60 | L43: 80000000 | M43: =L43 -> 80000000 | N43: =L43+M43/12 -> 86666667
I44: =I43+1 -> 2064 | J44: =J43+1 -> 61 | L44: 80000000 | M44: =L44 -> 80000000 | N44: =L44+M44/12 -> 86666667
I45: =I44+1 -> 2065 | J45: =J44+1 -> 62 | L45: 80000000 | M45: =L45 -> 80000000 | N45: =L45+M45/12 -> 86666667

Sheet 7. Human capital & pension valu
A1: Time Line | B1: 2024 | C1: 2025 | D1: =C1+1 -> 2026 | E1: =D1+1 -> 2027 | F1: =E1+1 -> 2028 | G1: =F1+1 -> 2029 | H1: =G1+1 -> 2030 | I1: =H1+1 -> 2031 | J1: =I1+1 -> 2032 | K1: =J1+1 -> 2033 | ... BN1: =BM1+1 -> 2088
A2: Period | B2: 0 | C2: 1 | D2: 2 | E2: =D2+1 -> 3 | F2: =E2+1 -> 4 | G2: =F2+1 -> 5 | H2: =G2+1 -> 6 | I2: =H2+1 -> 7 | J2: =I2+1 -> 8 | K2: =J2+1 -> 9 | L2: =K2+1 -> 10 | ... BN2: =BM2+1 -> 64
A3: Inflation rate | C3: ='3. Financial drivers '!G26 -> 0.0295 | D3: ='3. Financial drivers '!G27 -> 0.0249 | E3: ='3. Financial drivers '!G28 -> 0.028 | F3: ='3. Financial drivers '!G29 -> 0.029 | G3: ='3. Financial drivers '!G30 -> 0.029 | H3: ='3. Financial drivers '!G31 -> 0.029 | I3: ='3. Financial drivers '!$G$32 -> 0.02881 | J3: ='3. Financial drivers '!$G$32 -> 0.02881 | K3: ='3. Financial drivers '!$G$32 -> 0.02881 | L3: ='3. Financial drivers '!$G$32 -> 0.02881 | M3: ='3. Financial drivers '!$G$32 -> 0.02881 | N3: ='3. Financial drivers '!$G$32 -> 0.02881 | O3: ='3. Financial drivers '!$G$32 -> 0.02881 | P3: ='3. Financial drivers '!$G$32 -> 0.02881 | ... BN3: ='3. Financial drivers '!$G$32 -> 0.02881
A4: Huyen | C4: Bank Teller | F4: Controller | H4: Deputy Head of Customer Service | L4: Head of Customer Service | O4: Deputy Director of Operations | R4: Branch manager | AO4: Huyen retires | BN4: Pass away
A5: Huyen's husband | C5: Recruitment Assistant | F5: Recruitment Specialist | I5: Recruitment Team Leader | K5: Recruitment Manager | P5: Recruitment Director | T5: HR director | AQ5: Huyen's husband retires
A6: Young Children | H6: Give birth and Huyen's 6 months maternity leave | Z6: Start university | AD6: Become independent
A7: Our family | M7: Buy house and pay off mortgage | Z7: Buy car | AS7: Vacation period
A10: HUMAN CAPITAL
A11: Human captial - Huyen
A12: Pre tax income | C12: ='6. Salary'!G5*12 -> 179400000 | D12: =C12*(1+D3) -> 183867060 | E12: =D12*(1+E3) -> 1.8901534e+08 | F12: ='6. Salary'!G8*12 -> 228800000 | G12: =F12*(1+G3) -> 2.354352e+08 | H12: ='6. Salary'!G10*6 -> 130000000 | I12: ='6. Salary'!G10*12*(1+I3) -> 267490600 | J12: =I12*(1+J3) -> 2.75197e+08 | K12: =J12*(1+K3) -> 2.8312543e+08 | L12: ='6. Salary'!G14*12 -> 325000000 | M12: =L12*(1+M3) -> 334363250 | N12: =M12*(1+N3) -> 3.4399626e+08 | O12: ='6. Salary'!G17*12 -> 520000000 | P12: =O12*(1+P3) -> 534981200 | Q12: =P12*(1+Q3) -> 5.5039401e+08 | R12: ='6. Salary'!G20*12 -> 910000000 | S12: =R12*(1+S3) -> 936217100 | T12: =S12*(1+T3) -> 9.6318951e+08 | U12: =T12*(1+U3) -> 9.90939e+08 | V12: =U12*(1+V3) -> 1.019488e+09 | W12: =V12*(1+W3) -> 1.0488594e+09 | X12: =W12*(1+X3) -> 1.079077e+09 | Y12: =X12*(1+Y3) -> 1.1101653e+09 | Z12: =Y12*(1+Z3) -> 1.1421491e+09 | ... AO12: =AN12*(1+AO3) -> 1.7488415e+09
A13: Total deduction | C13: =11000000*12 -> 132000000 | D13: =11000000*12 -> 132000000 | E13: =11000000*12 -> 132000000 | F13: =11000000*12 -> 132000000 | G13: =11000000*12 -> 132000000 | H13: =11000000*6 -> 66000000 | I13: =11000000*12 -> 132000000 | J13: =11000000*12 -> 132000000 | K13: =11000000*12 -> 132000000 | L13: =11000000*12 -> 132000000 | M13: =11000000*12 -> 132000000 | N13: =11000000*12 -> 132000000 | O13: =11000000*12 -> 132000000 | P13: =11000000*12 -> 132000000 | ... AO13: =11000000*12 -> 132000000
A14: Social insurance | C14: =C12*$C$66 -> 18837000 | D14: =D12*$C$66 -> 19306041 | E14: =E12*$C$66 -> 19846610 | F14: =F12*$C$66 -> 24024000 | G14: =G12*$C$66 -> 24720696 | H14: =H12*$C$66 -> 13650000 | I14: =I12*$C$66 -> 28086513 | J14: =J12*$C$66 -> 28895685 | ... AO14: =AO12*$C$66 -> 1.8362836e+08
A15: Assessable income | C15: =C12-SUM(C13:C14) -> 28563000 | D15: =D12-SUM(D13:D14) -> 32561019 | E15: =E12-SUM(E13:E14) -> 37168727 | F15: =F12-SUM(F13:F14) -> 72776000 | G15: =G12-SUM(G13:G14) -> 78714504 | H15: =H12-SUM(H14) -> 116350000 | I15: =I12-SUM(I13:I14) -> 107404087 | J15: =J12-SUM(J13:J14) -> 1.1430132e+08 | K15: =K12-SUM(K13:K14) -> 1.2139726e+08 | L15: =L12-SUM(L13:L14) -> 158875000 | M15: =M12-SUM(M13:M14) -> 1.6725511e+08 | N15: =N12-SUM(N13:N14) -> 1.7587665e+08 | O15: =O12-SUM(O13:O14) -> 333400000 | P15: =P12-SUM(P13:P14) -> 346808174 | ... AO15: =AO12-SUM(AO13:AO14) -> 1.4332132e+09
A16: Income tax | C16: =IF(C15<=60000000,C15*0.5,IF(C15<=120000000,60000000*0.5+(C15-60000000)*0.1,IF(C15<=216000000,60000000*0.5+60000000*0.1+(C15-120000000)*0.15,IF(C15<=384000000,60000000*0.5+60000000*0.1+96000000*0.15+(C15-216000000)*0.2,IF(C15<=624000000,60000000*0.5+60000000*0.1+96000000*0.15+168000000*0.2+(C15-384000000)*0.25,IF(C15<=960000000,60000000*0.5+60000000*0.1+96000000*0.15+168000000*0.2+240000000*0.25+(C15-624000000)*0.3,60000000*0.5+60000000*0.1+96000000*0.15+168000000*0.2+240000000*0.25+336000000*0.3+(C15-960000000)*0.35)))))) -> 14281500 | D16: =IF(D15<=60000000,D15*0.5,IF(D15<=120000000,60000000*0.5+(D15-60000000)*0.1,IF(D15<=216000000,60000000*0.5+60000000*0.1+(D15-120000000)*0.15,IF(D15<=384000000,60000000*0.5+60000000*0.1+96000000*0.15+(D15-216000000)*0.2,IF(D15<=624000000,60000000*0.5+60000000*0.1+96000000*0.15+168000000*0.2+(D15-384000000)*0.25,IF(D15<=960000000,60000000*0.5+60000000*0.1+96000000*0.15+168000000*0.2+240000000*0.25+(D15-624000000)*0.3,60000000*0.5+60000000*0.1+96000000*0.15+168000000*0.2+240000000*0.25+336000000*0.3+(D15-960000000)*0.35)))))) -> 16280509 | E16: =IF(E15<=60000000,E15*0.5,IF(E15<=120000000,60000000*0.5+(E15-60000000)*0.1,IF(E15<=216000000,60000000*0.5+60000000*0.1+(E15-120000000)*0.15,IF(E15<=384000000,60000000*0.5+60000000*0.1+96000000*0.15+(E15-216000000)*0.2,IF(E15<=624000000,60000000*0.5+60000000*0.1+96000000*0.15+168000000*0.2+(E15-384000000)*0.25,IF(E15<=960000000,60000000*0.5+60000000*0.1+96000000*0.15+168000000*0.2+240000000*0.25+(E15-624000000)*0.3,60000000*0.5+60000000*0.1+96000000*0.15+168000000*0.2+240000000*0.25+336000000*0.3+(E15-960000000)*0.35)))))) -> 18584364 | F16: =IF(F15<=60000000,F15*0.5,IF(F15<=120000000,60000000*0.5+(F15-60000000)*0.1,IF(F15<=216000000,60000000*0.5+60000000*0.1+(F15-120000000)*0.15,IF(F15<=384000000,60000000*0.5+60000000*0.1+96000000*0.15+(F15-216000000)*0.2,IF(F15<=624000000,60000000*0.5+60000000*0.1+96000000*0.15+168000000*0.2+(F15-384000000)*0.25,IF(F15<=960000000,60000000*0.5+60000000*0.1+96000000*0.15+168000000*0.2+240000000*0.25+(F15-624000000)*0.3,60000000*0.5+60000000*0.1+96000000*0.15+168000000*0.2+240000000*0.25+336000000*0.3+(F15-960000000)*0.35)))))) -> 31277600 | G16: =IF(G15<=60000000,G15*0.5,IF(G15<=120000000,60000000*0.5+(G15-60000000)*0.1,IF(G15<=216000000,60000000*0.5+60000000*0.1+(G15-120000000)*0.15,IF(G15<=384000000,60000000*0.5+60000000*0.1+96000000*0.15+(G15-216000000)*0.2,IF(G15<=624000000,60000000*0.5+60000000*0.1+96000000*0.15+168000000*0.2+(G15-384000000)*0.25,IF(G15<=960000000,60000000*0.5+60000000*0.1+96000000*0.15+168000000*0.2+240000000*0.25+(G15-624000000)*0.3,60000000*0.5+60000000*0.1+96000000*0.15+168000000*0.2+240000000*0.25+336000000*0.3+(G15-960000000)*0.35)))))) -> 31871450 | H16: =IF(H15<=60000000,I15*0.5,IF(H15<=120000000,60000000*0.5+(H15-60000000)*0.1,IF(H15<=216000000,60000000*0.5+60000000*0.1+(H15-120000000)*0.15,IF(H15<=384000000,60000000*0.5+60000000*0.1+96000000*0.15+(H15-216000000)*0.2,IF(H15<=624000000,60000000*0.5+60000000*0.1+96000000*0.15+168000000*0.2+(H15-384000000)*0.25,IF(H15<=960000000,60000000*0.5+60000000*0.1+96000000*0.15+168000000*0.2+240000000*0.25+(H15-624000000)*0.3,60000000*0.5+60000000*0.1+96000000*0.15+168000000*0.2+240000000*0.25+336000000*0.3+(H15-960000000)*0.35)))))) -> 35635000 | I16: =IF(I15<=60000000,I15*0.5,IF(I15<=120000000,60000000*0.5+(I15-60000000)*0.1,IF(I15<=216000000,60000000*0.5+60000000*0.1+(I15-120000000)*0.15,IF(I15<=384000000,60000000*0.5+60000000*0.1+96000000*0.15+(I15-216000000)*0.2,IF(I15<=624000000,60000000*0.5+60000000*0.1+96000000*0.15+168000000*0.2+(I15-384000000)*0.25,IF(I15<=960000000,60000000*0.5+60000000*0.1+96000000*0.15+168000000*0.2+240000000*0.25+(I15-624000000)*0.3,60000000*0.5+60000000*0.1+96000000*0.15+168000000*0.2+240000000*0.25+336000000*0.3+(I15-960000000)*0.35)))))) -> 34740409 | J16: =IF(J15<=60000000,J15*0.5,IF(J15<=120000000,60000000*0.5+(J15-60000000)*0.1,IF(J15<=216000000,60000000*0.5+60000000*0.1+(J15-120000000)*0.15,IF(J15<=384000000,60000000*0.5+60000000*0.1+96000000*0.15+(J15-216000000)*0.2,IF(J15<=624000000,60000000*0.5+60000000*0.1+96000000*0.15+168000000*0.2+(J15-384000000)*0.25,IF(J15<=960000000,60000000*0.5+60000000*0.1+96000000*0.15+168000000*0.2+240000000*0.25+(J15-624000000)*0.3,60000000*0.5+60000000*0.1+96000000*0.15+168000000*0.2+240000000*0.25+336000000*0.3+(J15-960000000)*0.35)))))) -> 35430132 | K16: =IF(K15<=60000000,K15*0.5,IF(K15<=120000000,60000000*0.5+(K15-60000000)*0.1,IF(K15<=216000000,60000000*0.5+60000000*0.1+(K15-120000000)*0.15,IF(K15<=384000000,60000000*0.5+60000000*0.1+96000000*0.15+(K15-216000000)*0.2,IF(K15<=624000000,60000000*0.5+60000000*0.1+96000000*0.15+168000000*0.2+(K15-384000000)*0.25,IF(K15<=960000000,60000000*0.5+60000000*0.1+96000000*0.15+168000000*0.2+240000000*0.25+(K15-624000000)*0.3,60000000*0.5+60000000*0.1+96000000*0.15+168000000*0.2+240000000*0.25+336000000*0.3+(K15-960000000)*0.35)))))) -> 36209589 | L16: =IF(L15<=60000000,L15*0.5,IF(L15<=120000000,60000000*0.5+(L15-60000000)*0.1,IF(L15<=216000000,60000000*0.5+60000000*0.1+(L15-120000000)*0.15,IF(L15<=384000000,60000000*0.5+60000000*0.1+96000000*0.15+(L15-216000000)*0.2,IF(L15<=624000000,60000000*0.5+60000000*0.1+96000000*0.15+168000000*0.2+(L15-384000000)*0.25,IF(L15<=960000000,60000000*0.5+60000000*0.1+96000000*0.15+168000000*0.2+240000000*0.25+(L15-624000000)*0.3,60000000*0.5+60000000*0.1+96000000*0.15+168000000*0.2+240000000*0.25+336000000*0.3+(L15-960000000)*0.35)))))) -> 41831250 | M16: =IF(M15<=60000000,M15*0.5,IF(M15<=120000000,60000000*0.5+(M15-60000000)*0.1,IF(M15<=216000000,60000000*0.5+60000000*0.1+(M15-120000000)*0.15,IF(M15<=384000000,60000000*0.5+60000000*0.1+96000000*0.15+(M15-216000000)*0.2,IF(M15<=624000000,60000000*0.5+60000000*0.1+96000000*0.15+168000000*0.2+(M15-384000000)*0.25,IF(M15<=960000000,60000000*0.5+60000000*0.1+96000000*0.15+168000000*0.2+240000000*0.25+(M15-624000000)*0.3,60000000*0.5+60000000*0.1+96000000*0.15+168000000*0.2+240000000*0.25+336000000*0.3+(M15-960000000)*0.35)))))) -> 43088266 | N16: =IF(N15<=60000000,N15*0.5,IF(N15<=120000000,60000000*0.5+(N15-60000000)*0.1,IF(N15<=216000000,60000000*0.5+60000000*0.1+(N15-120000000)*0.15,IF(N15<=384000000,60000000*0.5+60000000*0.1+96000000*0.15+(N15-216000000)*0.2,IF(N15<=624000000,60000000*0.5+60000000*0.1+96000000*0.15+168000000*0.2+(N15-384000000)*0.25,IF(N15<=960000000,60000000*0.5+60000000*0.1+96000000*0.15+168000000*0.2+240000000*0.25+(N15-624000000)*0.3,60000000*0.5+60000000*0.1+96000000*0.15+168000000*0.2+240000000*0.25+336000000*0.3+(N15-960000000)*0.35)))))) -> 44381497 | O16: =IF(O15<=60000000,O15*0.5,IF(O15<=120000000,60000000*0.5+(O15-60000000)*0.1,IF(O15<=216000000,60000000*0.5+60000000*0.1+(O15-120000000)*0.15,IF(O15<=384000000,60000000*0.5+60000000*0.1+96000000*0.15+(O15-216000000)*0.2,IF(O15<=624000000,60000000*0.5+60000000*0.1+96000000*0.15+168000000*0.2+(O15-384000000)*0.25,IF(O15<=960000000,60000000*0.5+60000000*0.1+96000000*0.15+168000000*0.2+240000000*0.25+(O15-624000000)*0.3,60000000*0.5+60000000*0.1+96000000*0.15+168000000*0.2+240000000*0.25+336000000*0.3+(O15-960000000)*0.35)))))) -> 73880000 | P16: =IF(P15<=60000000,P15*0.5,IF(P15<=120000000,60000000*0.5+(P15-60000000)*0.1,IF(P15<=216000000,60000000*0.5+60000000*0.1+(P15-120000000)*0.15,IF(P15<=384000000,60000000*0.5+60000000*0.1+96000000*0.15+(P15-216000000)*0.2,IF(P15<=624000000,60000000*0.5+60000000*0.1+96000000*0.15+168000000*0.2+(P15-384000000)*0.25,IF(P15<=960000000,60000000*0.5+60000000*0.1+96000000*0.15+168000000*0.2+240000000*0.25+(P15-624000000)*0.3,60000000*0.5+60000000*0.1+96000000*0.15+168000000*0.2+240000000*0.25+336000000*0.3+(P15-960000000)*0.35)))))) -> 76561635 | ... AO16: =IF(AO15<=60000000,AO15*0.5,IF(AO15<=120000000,60000000*0.5+(AO15-60000000)*0.1,IF(AO15<=216000000,60000000*0.5+60000000*0.1+(AO15-120000000)*0.15,IF(AO15<=384000000,60000000*0.5+60000000*0.1+96000000*0.15+(AO15-216000000)*0.2,IF(AO15<=624000000,60000000*0.5+60000000*0.1+96000000*0.15+168000000*0.2+(AO15-384000000)*0.25,IF(AO15<=960000000,60000000*0.5+60000000*0.1+96000000*0.15+168000000*0.2+240000000*0.25+(AO15-624000000)*0.3,60000000*0.5+60000000*0.1+96000000*0.15+168000000*0.2+240000000*0.25+336000000*0.3+(AO15-960000000)*0.35)))))) -> 4.1042461e+08
A17: After tax income | C17: =C12-C16 -> 165118500 | D17: =D12-D16 -> 1.6758655e+08 | E17: =E12-E16 -> 1.7043097e+08 | F17: =F12-F16 -> 197522400 | G17: =G12-G16 -> 2.0356375e+08 | H17: =H12-H16 -> 94365000 | I17: =I12-I16 -> 2.3275019e+08 | J17: =J12-J16 -> 2.3976687e+08 | ... AO17: =AO12-AO16 -> 1.3384169e+09
A18: Present value of future income | C18: =C17 -> 165118500 | D18: =D17/((1+$C$64)^D2) -> 1.4644775e+08 | E18: =E17/((1+$C$64)^E2) -> 1.3922391e+08 | F18: =F17/(1+$C$64)^F2 -> 1.5083545e+08 | G18: =G17/(1+$C$64)^G2 -> 1.453146e+08 | H18: =H17/(1+$C$64)^H2 -> 62971137 | I18: =I17/(1+$C$64)^I2 -> 1.451919e+08 | J18: =J17/(1+$C$64)^J2 -> 1.3981807e+08 | K18: =K17/(1+$C$64)^K2 -> 1.3459993e+08 | L18: =L17/(1+$C$64)^L2 -> 1.4429888e+08 | M18: =M17/(1+$C$64)^M2 -> 1.3875307e+08 | ... AO18: =AO17/(1+$C$64)^AO2 -> 96547324
A19: Age of Huyen | C19: 22 | D19: =C19+1 -> 23 | E19: =D19+1 -> 24 | F19: =E19+1 -> 25 | G19: =F19+1 -> 26 | H19: =G19+1 -> 27 | I19: =H19+1 -> 28 | J19: =I19+1 -> 29 | K19: =J19+1 -> 30 | ... AO19: =AN19+1 -> 60
A20: Probability of surviving | C20: =1-0.000416227 -> 0.99958377 | D20: =1-0.000416227 -> 0.99958377 | E20: =1-0.000416227 -> 0.99958377 | F20: =1-0.000472252 -> 0.99952775 | G20: =1-0.000472252 -> 0.99952775 | H20: =1-0.000472252 -> 0.99952775 | I20: =1-0.000472252 -> 0.99952775 | J20: =1-0.000472252 -> 0.99952775 | K20: =1-0.000615292 -> 0.99938471 | L20: =1-0.000615292 -> 0.99938471 | M20: =1-0.000615292 -> 0.99938471 | N20: =1-0.000615292 -> 0.99938471 | O20: =1-0.000615292 -> 0.99938471 | P20: =1-0.000912829 -> 0.99908717 | Q20: =1-0.000912829 -> 0.99908717 | R20: =1-0.000912829 -> 0.99908717 | S20: =1-0.000912829 -> 0.99908717 | T20: =1-0.000912829 -> 0.99908717 | U20: =1-0.001452051 -> 0.99854795 | V20: =1-0.001452051 -> 0.99854795 | W20: =1-0.001452051 -> 0.99854795 | X20: =1-0.001452051 -> 0.99854795 | Y20: =1-0.001452051 -> 0.99854795 | Z20: =1-0.002280473 -> 0.99771953 | AA20: =1-0.002280473 -> 0.99771953 | AB20: =1-0.002280473 -> 0.99771953 | AC20: =1-0.002280473 -> 0.99771953 | AD20: =1-0.002280473 -> 0.99771953 | AE20: =1-0.003585945 -> 0.99641406 | AF20: =1-0.003585945 -> 0.99641406 | AG20: =1-0.003585945 -> 0.99641406 | AH20: =1-0.003585945 -> 0.99641406 | AI20: =1-0.003585945 -> 0.99641406 | AJ20: =1-0.005487598 -> 0.9945124 | AK20: =1-0.005487598 -> 0.9945124 | AL20: =1-0.005487598 -> 0.9945124 | AM20: =1-0.005487598 -> 0.9945124 | AN20: =1-0.005487598 -> 0.9945124 | AO20: =1-0.008891343 -> 0.99110866
A21: Human capital | C21: =SUMPRODUCT(C18:AO18,C20:AO20) -> 6.0981099e+09
A24: Human captial - Huyen's husband
A25: Pre tax income | C25: ='6. Salary'!N5*12 -> 195000000 | D25: =C25*(1+D3) -> 1.998555e+08 | E25: =D25*(1+E3) -> 2.0545145e+08 | F25: ='6. Salary'!N8*12 -> 260000000 | G25: =F25*(1+G3) -> 2.6754e+08 | H25: =G25*(1+H3) -> 2.7529866e+08 | I25: ='6. Salary'!N11*12 -> 325000000 | J25: =I25*(1+J3) -> 334363250 | K25: ='6. Salary'!N13*12 -> 455000000 | L25: =K25*(1+L3) -> 468108550 | M25: =L25*(1+M3) -> 4.8159476e+08 | N25: =M25*(1+N3) -> 4.954695e+08 | O25: =N25*(1+O3) -> 5.0974398e+08 | P25: ='6. Salary'!N18*12 -> 585000000 | Q25: =P25*(1+Q3) -> 601853850 | R25: =Q25*(1+R3) -> 6.1919326e+08 | S25: =R25*(1+S3) -> 6.3703222e+08 | T25: ='6. Salary'!N22*12 -> 1040000000 | U25: =T25*(1+U3) -> 1069962400 | V25: =U25*(1+V3) -> 1.100788e+09 | W25: =V25*(1+W3) -> 1.1325017e+09 | X25: =W25*(1+X3) -> 1.1651291e+09 | Y25: =X25*(1+Y3) -> 1.1986965e+09 | Z25: =Y25*(1+Z3) -> 1.2332309e+09 | AA25: =Z25*(1+AA3) -> 1.2687603e+09 | AB25: =AA25*(1+AB3) -> 1.3053133e+09 | ... AQ25: =AP25*(1+AQ3) -> 1.9986761e+09
A26: Total deduction | C26: =11000000*12 -> 132000000 | D26: =11000000*12 -> 132000000 | E26: =11000000*12 -> 132000000 | F26: =11000000*12 -> 132000000 | G26: =11000000*12 -> 132000000 | H26: =11000000*12+4400000*12 -> 184800000 | I26: =11000000*12+4400000*12 -> 184800000 | J26: =11000000*12+4400000*12 -> 184800000 | K26: =11000000*12+4400000*12 -> 184800000 | L26: =11000000*12+4400000*12 -> 184800000 | M26: =11000000*12+4400000*12 -> 184800000 | N26: =11000000*12+4400000*12 -> 184800000 | O26: =11000000*12+4400000*12 -> 184800000 | ... AQ26: =11000000*12+4400000*12 -> 184800000
A27: Social insurance | C27: =C25*$C$66 -> 20475000 | D27: =D25*$C$66 -> 20984827 | E27: =E25*$C$66 -> 21572403 | F27: =F25*$C$66 -> 27300000 | G27: =G25*$C$66 -> 28091700 | H27: =H25*$C$66 -> 28906359 | I27: =I25*$C$66 -> 34125000 | J27: =J25*$C$66 -> 35108141 | ... AQ27: =AQ25*$C$66 -> 2.0986099e+08
A28: Assessable income | C28: =C25-SUM(C26:C27) -> 42525000 | D28: =D25-SUM(D26:D27) -> 46870672 | E28: =E25-SUM(E26:E27) -> 51879051 | F28: =F25-SUM(F26:F27) -> 100700000 | G28: =G25-SUM(G26:G27) -> 1.074483e+08 | H28: =H25-SUM(H26:H27) -> 61592301 | I28: =I25-SUM(I26:I27) -> 106075000 | J28: =J25-SUM(J26:J27) -> 1.1445511e+08 | ... AQ28: =AQ25-SUM(AQ26:AQ27) -> 1.6040151e+09
A29: Income tax | C29: =IF(C28<=60000000,C28*0.5,IF(C28<=120000000,60000000*0.5+(C28-60000000)*0.1,IF(C28<=216000000,60000000*0.5+60000000*0.1+(C28-120000000)*0.15,IF(C28<=384000000,60000000*0.5+60000000*0.1+96000000*0.15+(C28-216000000)*0.2,IF(C28<=624000000,60000000*0.5+60000000*0.1+96000000*0.15+168000000*0.2+(C28-384000000)*0.25,IF(C28<=960000000,60000000*0.5+60000000*0.1+96000000*0.15+168000000*0.2+240000000*0.25+(C28-624000000)*0.3,60000000*0.5+60000000*0.1+96000000*0.15+168000000*0.2+240000000*0.25+336000000*0.3+(C28-960000000)*0.35)))))) -> 21262500 | D29: =IF(D28<=60000000,D28*0.5,IF(D28<=120000000,60000000*0.5+(D28-60000000)*0.1,IF(D28<=216000000,60000000*0.5+60000000*0.1+(D28-120000000)*0.15,IF(D28<=384000000,60000000*0.5+60000000*0.1+96000000*0.15+(D28-216000000)*0.2,IF(D28<=624000000,60000000*0.5+60000000*0.1+96000000*0.15+168000000*0.2+(D28-384000000)*0.25,IF(D28<=960000000,60000000*0.5+60000000*0.1+96000000*0.15+168000000*0.2+240000000*0.25+(D28-624000000)*0.3,60000000*0.5+60000000*0.1+96000000*0.15+168000000*0.2+240000000*0.25+336000000*0.3+(D28-960000000)*0.35)))))) -> 23435336 | E29: =IF(E28<=60000000,E28*0.5,IF(E28<=120000000,60000000*0.5+(E28-60000000)*0.1,IF(E28<=216000000,60000000*0.5+60000000*0.1+(E28-120000000)*0.15,IF(E28<=384000000,60000000*0.5+60000000*0.1+96000000*0.15+(E28-216000000)*0.2,IF(E28<=624000000,60000000*0.5+60000000*0.1+96000000*0.15+168000000*0.2+(E28-384000000)*0.25,IF(E28<=960000000,60000000*0.5+60000000*0.1+96000000*0.15+168000000*0.2+240000000*0.25+(E28-624000000)*0.3,60000000*0.5+60000000*0.1+96000000*0.15+168000000*0.2+240000000*0.25+336000000*0.3+(E28-960000000)*0.35)))))) -> 25939526 | F29: =IF(F28<=60000000,F28*0.5,IF(F28<=120000000,60000000*0.5+(F28-60000000)*0.1,IF(F28<=216000000,60000000*0.5+60000000*0.1+(F28-120000000)*0.15,IF(F28<=384000000,60000000*0.5+60000000*0.1+96000000*0.15+(F28-216000000)*0.2,IF(F28<=624000000,60000000*0.5+60000000*0.1+96000000*0.15+168000000*0.2+(F28-384000000)*0.25,IF(F28<=960000000,60000000*0.5+60000000*0.1+96000000*0.15+168000000*0.2+240000000*0.25+(F28-624000000)*0.3,60000000*0.5+60000000*0.1+96000000*0.15+168000000*0.2+240000000*0.25+336000000*0.3+(F28-960000000)*0.35)))))) -> 34070000 | G29: =IF(G28<=60000000,G28*0.5,IF(G28<=120000000,60000000*0.5+(G28-60000000)*0.1,IF(G28<=216000000,60000000*0.5+60000000*0.1+(G28-120000000)*0.15,IF(G28<=384000000,60000000*0.5+60000000*0.1+96000000*0.15+(G28-216000000)*0.2,IF(G28<=624000000,60000000*0.5+60000000*0.1+96000000*0.15+168000000*0.2+(G28-384000000)*0.25,IF(G28<=960000000,60000000*0.5+60000000*0.1+96000000*0.15+168000000*0.2+240000000*0.25+(G28-624000000)*0.3,60000000*0.5+60000000*0.1+96000000*0.15+168000000*0.2+240000000*0.25+336000000*0.3+(G28-960000000)*0.35)))))) -> 34744830 | H29: =IF(H28<=60000000,H28*0.5,IF(H28<=120000000,60000000*0.5+(H28-60000000)*0.1,IF(H28<=216000000,60000000*0.5+60000000*0.1+(H28-120000000)*0.15,IF(H28<=384000000,60000000*0.5+60000000*0.1+96000000*0.15+(H28-216000000)*0.2,IF(H28<=624000000,60000000*0.5+60000000*0.1+96000000*0.15+168000000*0.2+(H28-384000000)*0.25,IF(H28<=960000000,60000000*0.5+60000000*0.1+96000000*0.15+168000000*0.2+240000000*0.25+(H28-624000000)*0.3,60000000*0.5+60000000*0.1+96000000*0.15+168000000*0.2+240000000*0.25+336000000*0.3+(H28-960000000)*0.35)))))) -> 30159230 | I29: =IF(I28<=60000000,I28*0.5,IF(I28<=120000000,60000000*0.5+(I28-60000000)*0.1,IF(I28<=216000000,60000000*0.5+60000000*0.1+(I28-120000000)*0.15,IF(I28<=384000000,60000000*0.5+60000000*0.1+96000000*0.15+(I28-216000000)*0.2,IF(I28<=624000000,60000000*0.5+60000000*0.1+96000000*0.15+168000000*0.2+(I28-384000000)*0.25,IF(I28<=960000000,60000000*0.5+60000000*0.1+96000000*0.15+168000000*0.2+240000000*0.25+(I28-624000000)*0.3,60000000*0.5+60000000*0.1+96000000*0.15+168000000*0.2+240000000*0.25+336000000*0.3+(I28-960000000)*0.35)))))) -> 34607500 | J29: =IF(J28<=60000000,J28*0.5,IF(J28<=120000000,60000000*0.5+(J28-60000000)*0.1,IF(J28<=216000000,60000000*0.5+60000000*0.1+(J28-120000000)*0.15,IF(J28<=384000000,60000000*0.5+60000000*0.1+96000000*0.15+(J28-216000000)*0.2,IF(J28<=624000000,60000000*0.5+60000000*0.1+96000000*0.15+168000000*0.2+(J28-384000000)*0.25,IF(J28<=960000000,60000000*0.5+60000000*0.1+96000000*0.15+168000000*0.2+240000000*0.25+(J28-624000000)*0.3,60000000*0.5+60000000*0.1+96000000*0.15+168000000*0.2+240000000*0.25+336000000*0.3+(J28-960000000)*0.35)))))) -> 35445511 | ... AQ29: =IF(AQ28<=60000000,AQ28*0.5,IF(AQ28<=120000000,60000000*0.5+(AQ28-60000000)*0.1,IF(AQ28<=216000000,60000000*0.5+60000000*0.1+(AQ28-120000000)*0.15,IF(AQ28<=384000000,60000000*0.5+60000000*0.1+96000000*0.15+(AQ28-216000000)*0.2,IF(AQ28<=624000000,60000000*0.5+60000000*0.1+96000000*0.15+168000000*0.2+(AQ28-384000000)*0.25,IF(AQ28<=960000000,60000000*0.5+60000000*0.1+96000000*0.15+168000000*0.2+240000000*0.25+(AQ28-624000000)*0.3,60000000*0.5+60000000*0.1+96000000*0.15+168000000*0.2+240000000*0.25+336000000*0.3+(AQ28-960000000)*0.35)))))) -> 4.7020527e+08
A30: After tax income | C30: =C25-C29 -> 173737500 | D30: =D25-D29 -> 1.7642016e+08 | E30: =E25-E29 -> 1.7951193e+08 | F30: =F25-F29 -> 225930000 | G30: =G25-G29 -> 2.3279517e+08 | H30: =H25-H29 -> 2.4513943e+08 | I30: =I25-I29 -> 290392500 | J30: =J25-J29 -> 2.9891774e+08 | ... AQ30: =AQ25-AQ29 -> 1.5284708e+09
A31: Present value of future income | C31: =C30 -> 173737500 | D31: =D30/(1+$C$65)^D2 -> 1.5416712e+08 | E31: =E30/(1+$C$65)^E2 -> 1.4664208e+08 | F31: =F30/(1+$C$65)^F2 -> 1.7252855e+08 | G31: =G30/(1+$C$65)^G2 -> 1.6618154e+08 | H31: =H30/(1+$C$65)^H2 -> 1.6358511e+08 | I31: =I30/(1+$C$65)^I2 -> 1.8114975e+08 | J31: =J30/(1+$C$65)^J2 -> 1.7431141e+08 | K31: =K30/(1+$C$65)^K2 -> 2.1985698e+08 | ... AQ31: =AQ30/(1+$C$65)^AQ2 -> 96349506
A32: Age of Huyen's husband | C32: 22 | D32: =C32+1 -> 23 | E32: =D32+1 -> 24 | F32: =E32+1 -> 25 | G32: =F32+1 -> 26 | H32: =G32+1 -> 27 | I32: =H32+1 -> 28 | J32: =I32+1 -> 29 | K32: =J32+1 -> 30 | ... AQ32: =AP32+1 -> 62
A33: Probability of surviving | C33: =1-0.00148833 -> 0.99851167 | D33: =1-0.00148833 -> 0.99851167 | E33: =1-0.00148833 -> 0.99851167 | F33: =1-0.001467648 -> 0.99853235 | G33: =1-0.001467648 -> 0.99853235 | H33: =1-0.001467648 -> 0.99853235 | I33: =1-0.001467648 -> 0.99853235 | J33: =1-0.001467648 -> 0.99853235 | K33: =1-0.001691763 -> 0.99830824 | L33: =1-0.001691763 -> 0.99830824 | M33: =1-0.001691763 -> 0.99830824 | N33: =1-0.001691763 -> 0.99830824 | O33: =1-0.001691763 -> 0.99830824 | P33: =1-0.002338274 -> 0.99766173 | Q33: =1-0.002338274 -> 0.99766173 | R33: =1-0.002338274 -> 0.99766173 | S33: =1-0.002338274 -> 0.99766173 | T33: =1-0.002338274 -> 0.99766173 | U33: =1-0.003645446 -> 0.99635455 | V33: =1-0.003645446 -> 0.99635455 | W33: =1-0.003645446 -> 0.99635455 | X33: =1-0.003645446 -> 0.99635455 | Y33: =1-0.003645446 -> 0.99635455 | Z33: =1-0.005916506 -> 0.99408349 | AA33: =1-0.005916506 -> 0.99408349 | AB33: =1-0.005916506 -> 0.99408349 | AC33: =1-0.005916506 -> 0.99408349 | AD33: =1-0.005916506 -> 0.99408349 | AE33: =1-0.00947506 -> 0.99052494 | AF33: =1-0.00947506 -> 0.99052494 | AG33: =1-0.00947506 -> 0.99052494 | AH33: =1-0.00947506 -> 0.99052494 | AI33: =1-0.00947506 -> 0.99052494 | AJ33: =1-0.014665436 -> 0.98533456 | AK33: =1-0.014665436 -> 0.98533456 | AL33: =1-0.014665436 -> 0.98533456 | AM33: =1-0.014665436 -> 0.98533456 | AN33: =1-0.014665436 -> 0.98533456 | AO33: =1-0.022502985 -> 0.97749701 | AP33: =1-0.022502985 -> 0.97749701 | AQ33: =1-0.022502985 -> 0.97749701
A34: Human capital | C34: =SUMPRODUCT(C33:AQ33,C31:AQ31) -> 6.9863372e+09
A36: Total human capital | C36: =C34+C21 -> 1.3084447e+10
A39: PENSION VALUE
A40: Pension value - Huyen
A41: Age of Huyen | AP41: 61 | AQ41: =AP41+1 -> 62 | AR41: =AQ41+1 -> 63 | AS41: =AR41+1 -> 64 | AT41: =AS41+1 -> 65 | AU41: =AT41+1 -> 66 | AV41: =AU41+1 -> 67 | AW41: =AV41+1 -> 68 | AX41: =AW41+1 -> 69 | ... BN41: =BM41+1 -> 85
A42: Probability of surviving | AP42: =1-0.008891343 -> 0.99110866 | AQ42: =1-0.008891343 -> 0.99110866 | AR42: =1-0.008891343 -> 0.99110866 | AS42: =1-0.008891343 -> 0.99110866 | AT42: =1-0.014746672 -> 0.98525333 | AU42: =1-0.014746672 -> 0.98525333 | AV42: =1-0.014746672 -> 0.98525333 | AW42: =1-0.014746672 -> 0.98525333 | AX42: =1-0.014746672 -> 0.98525333 | AY42: =1-0.025760369 -> 0.97423963 | AZ42: =1-0.025760369 -> 0.97423963 | BA42: =1-0.025760369 -> 0.97423963 | BB42: =1-0.025760369 -> 0.97423963 | BC42: =1-0.025760369 -> 0.97423963 | BD42: =1-0.044856567 -> 0.95514343 | BE42: =1-0.044856567 -> 0.95514343 | BF42: =1-0.044856567 -> 0.95514343 | BG42: =1-0.044856567 -> 0.95514343 | BH42: =1-0.044856567 -> 0.95514343 | BI42: =1-0.080907942 -> 0.91909206 | BJ42: =1-0.080907942 -> 0.91909206 | BK42: =1-0.080907942 -> 0.91909206 | BL42: =1-0.080907942 -> 0.91909206 | BM42: =1-0.080907942 -> 0.91909206 | BN42: =1-0.169725066 -> 0.83027493
A43: Pension | AP43: =$C$69 -> 5.4576416e+08 | AQ43: =$C$69 -> 5.4576416e+08 | AR43: =$C$69 -> 5.4576416e+08 | AS43: =$C$69 -> 5.4576416e+08 | AT43: =$C$69 -> 5.4576416e+08 | AU43: =$C$69 -> 5.4576416e+08 | AV43: =$C$69 -> 5.4576416e+08 | AW43: =$C$69 -> 5.4576416e+08 | ... BN43: =$C$69 -> 5.4576416e+08
A44: Present value of pension | AP44: =AP43/(1+$C$72)^AP2 -> 1.3923727e+08 | AQ44: =AQ43/(1+$C$72)^AQ2 -> 1.3456256e+08 | AR44: =AR43/(1+$C$72)^AR2 -> 1.3004481e+08 | AS44: =AS43/(1+$C$72)^AS2 -> 1.2567873e+08 | AT44: =AT43/(1+$C$72)^AT2 -> 1.2145923e+08 | AU44: =AU43/(1+$C$72)^AU2 -> 1.173814e+08 | AV44: =AV43/(1+$C$72)^AV2 -> 1.1344048e+08 | AW44: =AW43/(1+$C$72)^AW2 -> 1.0963187e+08 | ... BN44: =BN43/(1+$C$72)^BN2 -> 61348759
A45: Pension value | AP45: =SUMPRODUCT(AP44:BN44,AP42:BN42) -> 2.2998207e+09
A48: Pension value - Huyen's husband
A49: Age of Huyen's husband | AR49: 63 | AS49: =AR49+1 -> 64 | AT49: =AS49+1 -> 65 | AU49: =AT49+1 -> 66 | AV49: =AU49+1 -> 67 | AW49: =AV49+1 -> 68 | AX49: =AW49+1 -> 69 | AY49: =AX49+1 -> 70 | AZ49: =AY49+1 -> 71 | ... BN49: =BM49+1 -> 85
...

Sheet 8. Budget Estimate
A1: Time Line | B1: 2024 | C1: 2025 | D1: =C1+1 -> 2026 | E1: =D1+1 -> 2027 | F1: =E1+1 -> 2028 | G1: =F1+1 -> 2029 | H1: =G1+1 -> 2030 | I1: =H1+1 -> 2031 | J1: =I1+1 -> 2032 | K1: =J1+1 -> 2033 | ... BN1: =BM1+1 -> 2088
A2: Period | B2: 0 | C2: 1 | D2: 2 | E2: =D2+1 -> 3 | F2: =E2+1 -> 4 | G2: =F2+1 -> 5 | H2: =G2+1 -> 6 | I2: =H2+1 -> 7 | J2: =I2+1 -> 8 | K2: =J2+1 -> 9 | L2: =K2+1 -> 10 | ... BN2: =BM2+1 -> 64
A3: Inflation rate | C3: ='3. Financial drivers '!G26 -> 0.0295 | D3: ='3. Financial drivers '!G27 -> 0.0249 | E3: ='3. Financial drivers '!G28 -> 0.028 | F3: ='3. Financial drivers '!G29 -> 0.029 | G3: ='3. Financial drivers '!G30 -> 0.029 | H3: ='3. Financial drivers '!G31 -> 0.029 | I3: ='3. Financial drivers '!$G$32 -> 0.02881 | J3: ='3. Financial drivers '!$G$32 -> 0.02881 | K3: ='3. Financial drivers '!$G$32 -> 0.02881 | L3: ='3. Financial drivers '!$G$32 -> 0.02881 | M3: ='3. Financial drivers '!$G$32 -> 0.02881 | N3: ='3. Financial drivers '!$G$32 -> 0.02881 | O3: ='3. Financial drivers '!$G$32 -> 0.02881 | P3: ='3. Financial drivers '!$G$32 -> 0.02881 | ... BN3: ='3. Financial drivers '!$G$32 -> 0.02881
A4: Huyen | C4: Bank Teller | F4: Controller | H4: Deputy Head of Customer Service | L4: Head of Customer Service | O4: Deputy Director of Operations | R4: Branch manager | AO4: Huyen retires | BN4: Pass away
A5: Huyen's husband | C5: Recruitment Assistant | F5: Recruitment Specialist | I5: Recruitment Team Leader | K5: Recruitment Manager | P5: Recruitment Director | AQ5: Huyen's husband retires
A6: Young Children | H6: Give birth and Huyen's 6 months maternity leave | Z6: Start university | AD6: Become independent
A7: Our family | M7: Buy house and pay off mortgage | Z7: Buy car
A10: INCOME
A11: Huyen's pre tax income | C11: ='7. Human capital & pension valu'!C12 -> 179400000 | D11: ='7. Human capital & pension valu'!D12 -> 183867060 | E11: ='7. Human capital & pension valu'!E12 -> 1.8901534e+08 | F11: ='7. Human capital & pension valu'!F12 -> 228800000 | G11: ='7. Human capital & pension valu'!G12 -> 2.354352e+08 | H11: ='7. Human capital & pension valu'!H12 -> 130000000 | I11: ='7. Human capital & pension valu'!I12 -> 267490600 | J11: ='7. Human capital & pension valu'!J12 -> 2.75197e+08 | ... AO11: ='7. Human capital & pension valu'!AO12 -> 1.7488415e+09 | AP11: ='7. Human capital & pension valu'!AP43 -> 5.4576416e+08 | AQ11: ='7. Human capital & pension valu'!AQ43 -> 5.4576416e+08
A12: Huyen's husband pre tax income | C12: ='7. Human capital & pension valu'!C25 -> 195000000 | D12: ='7. Human capital & pension valu'!D25 -> 1.998555e+08 | E12: ='7. Human capital & pension valu'!E25 -> 2.0545145e+08 | F12: ='7. Human capital & pension valu'!F25 -> 260000000 | G12: ='7. Human capital & pension valu'!G25 -> 2.6754e+08 | H12: ='7. Human capital & pension valu'!H25 -> 2.7529866e+08 | I12: ='7. Human capital & pension valu'!I25 -> 325000000 | J12: ='7. Human capital & pension valu'!J25 -> 334363250 | ... AQ12: ='7. Human capital & pension valu'!AQ25 -> 1.9986761e+09
A13: Interest | C13: {=TRANSPOSE('21. Monte Carlo Simulation '!Q3:Q43)} -> 3920000 | D13: 0 | E13: 0 | F13: 0 | G13: 1837179.1 | H13: 1792212.6 | I13: 5297777.5 | J13: 3557837.3 | K13: 6972159.3 | L13: 11439652 | M13: 40624670 | N13: 26024235 | O13: 22992530 | P13: 22871510 | Q13: 22164605 | R13: 33202379 | S13: 25321541 | T13: -6585607.2 | U13: 98398762 | V13: 1.7412314e+08 | W13: 1.9690751e+08 | X13: 2.9067312e+08 | Y13: 4.277708e+08 | Z13: 4.9884844e+08 | AA13: 75244092 | AB13: 1.6795618e+08 | AC13: 5.843437e+08 | AD13: 6.2257326e+08 | AE13: 6.2301053e+08 | AF13: 6.4894396e+08 | AG13: 1.0352482e+09 | AH13: 9.2352626e+08 | AI13: 1.0896735e+09 | AJ13: 1.4534354e+09 | AK13: 1.5288757e+09 | AL13: 1.4993755e+09 | AM13: 1.4560202e+09 | AN13: 2.5421175e+09 | AO13: 2.6341084e+09 | AP13: 2.030789e+09 | AQ13: 2.0863531e+09
A14: Total income | C14: =SUM(C11:C13) -> 378320000 | D14: =SUM(D11:D13) -> 383722560 | E14: =SUM(E11:E13) -> 3.9446679e+08 | F14: =SUM(F11:F13) -> 488800000 | G14: =SUM(G11:G13) -> 5.0481238e+08 | H14: =SUM(H11:H13) -> 4.0709087e+08 | I14: =SUM(I11:I13) -> 5.9778838e+08 | J14: =SUM(J11:J13) -> 6.1311809e+08 | ... AQ14: =SUM(AQ11:AQ13) -> 4.6307933e+09
A16: EXPENSE
A17: Rent | C17: =8000000*12 -> 96000000 | D17: =C17*(1+$D$3) -> 98390400 | E17: =D17*(1+$E$3) -> 1.0114533e+08 | F17: =E17*(1+$F$3) -> 1.0407855e+08 | G17: =F17*(1+$G$3) -> 1.0709682e+08 | H17: =G17*(1+$H$3) -> 1.1020263e+08 | I17: =H17*(1+$I$3) -> 1.1337757e+08 | J17: =I17*(1+$I$3) -> 1.1664398e+08 | K17: =J17*(1+$I$3) -> 1.2000449e+08 | L17: =K17*(1+$I$3) -> 1.2346182e+08
A18: Food | C18: =6000000*12 -> 72000000 | D18: =C18*(1+$D$3) -> 73792800 | E18: =D18*(1+$E$3) -> 75858998 | F18: =E18*(1+$F$3) -> 78058909 | G18: =F18*(1+$G$3) -> 80322618 | H18: =G18*(1+$H$3) -> 82651974 | I18: =H18*(1+$I$3) -> 85033177 | J18: =I18*(1+$I$3) -> 87482983 | K18: =J18*(1+$I$3) -> 90003368 | L18: =K18*(1+$I$3) -> 92596365 | M18: =L18*(1+$I$3) -> 95264066 | N18: =M18*(1+$I$3) -> 98008624 | O18: =N18*(1+$I$3) -> 1.0083225e+08 | P18: =O18*(1+$I$3) -> 1.0373723e+08 | ... AQ18: =AP18*(1+$I$3) -> 2.2334921e+08
A19: Necessities | C19: =2000000*12 -> 24000000 | D19: =C19*(1+$D$3) -> 24597600 | E19: =D19*(1+$E$3) -> 25286333 | F19: =E19*(1+$F$3) -> 26019636 | G19: =F19*(1+$G$3) -> 26774206 | H19: =G19*(1+$H$3) -> 27550658 | I19: =H19*(1+$I$3) -> 28344392 | J19: =I19*(1+$I$3) -> 29160994 | K19: =J19*(1+$I$3) -> 30001123 | L19: =K19*(1+$I$3) -> 30865455 | M19: =L19*(1+$I$3) -> 31754689 | N19: =M19*(1+$I$3) -> 32669541 | O19: =N19*(1+$I$3) -> 33610751 | P19: =O19*(1+$I$3) -> 34579076 | ... AQ19: =AP19*(1+$I$3) -> 74449737
A20: Electric and water | C20: =1500000*12 -> 18000000 | D20: =C20*(1+$D$3) -> 18448200 | E20: =D20*(1+$E$3) -> 18964750 | F20: =E20*(1+$F$3) -> 19514727 | G20: =F20*(1+$G$3) -> 20080654 | H20: =G20*(1+$H$3) -> 20662993 | I20: =H20*(1+$I$3) -> 21258294 | J20: =I20*(1+$I$3) -> 21870746 | K20: =J20*(1+$I$3) -> 22500842 | L20: =K20*(1+$I$3) -> 23149091 | M20: =L20*(1+$I$3) -> 23816016 | N20: =M20*(1+$I$3) -> 24502156 | O20: =N20*(1+$I$3) -> 25208063 | P20: =O20*(1+$I$3) -> 25934307 | ... AQ20: =AP20*(1+$I$3) -> 55837303
A21: Phone and internet | C21: =150000*12 -> 1800000 | D21: =C21*(1+$D$3) -> 1844820 | E21: =D21*(1+$E$3) -> 1896475 | F21: =E21*(1+$F$3) -> 1951472.7 | G21: =F21*(1+$G$3) -> 2008065.4 | H21: =G21*(1+$H$3) -> 2066299.3 | I21: =H21*(1+$I$3) -> 2125829.4 | J21: =I21*(1+$I$3) -> 2187074.6 | K21: =J21*(1+$I$3) -> 2250084.2 | L21: =K21*(1+$I$3) -> 2314909.1 | M21: =L21*(1+$I$3) -> 2381601.6 | N21: =M21*(1+$I$3) -> 2450215.6 | O21: =N21*(1+$I$3) -> 2520806.3 | P21: =O21*(1+$I$3) -> 2593430.7 | ... AQ21: =AP21*(1+$I$3) -> 5583730.3
A22: Fuel and gas | C22: =350000*12 -> 4200000 | D22: =C22*(1+$D$3) -> 4304580 | E22: =D22*(1+$E$3) -> 4425108.2 | F22: =E22*(1+$F$3) -> 4553436.4 | G22: =F22*(1+$G$3) -> 4685486 | H22: =G22*(1+$H$3) -> 4821365.1 | I22: =H22*(1+$I$3) -> 4960268.7 | J22: =I22*(1+$I$3) -> 5103174 | K22: =J22*(1+$I$3) -> 5250196.4 | L22: =K22*(1+$I$3) -> 5401454.6 | M22: =L22*(1+$I$3) -> 5557070.5 | N22: =M22*(1+$I$3) -> 5717169.7 | O22: =N22*(1+$I$3) -> 5881881.4 | P22: =O22*(1+$I$3) -> 6051338.4 | ... AQ22: =AP22*(1+$I$3) -> 13028704
A23: Parking | C23: =200000*12 -> 2400000 | D23: =C23*(1+$D$3) -> 2459760 | E23: =D23*(1+$E$3) -> 2528633.3 | F23: =E23*(1+$F$3) -> 2601963.6 | G23: =F23*(1+$G$3) -> 2677420.6 | H23: =G23*(1+$H$3) -> 2755065.8 | I23: =H23*(1+I3) -> 2834439.2 | J23: =I23*(1+J3) -> 2916099.4 | K23: =J23*(1+K3) -> 3000112.3 | L23: =K23*(1+L3) -> 3086545.5 | M23: =L23*(1+M3) -> 3175468.9 | N23: =M23*(1+N3) -> 3266954.1 | O23: =N23*(1+O3) -> 3361075.1 | P23: =O23*(1+P3) -> 3457907.6 | ... AQ23: =AP23*(1+AQ3) -> 7444973.7
A24: Skincare and comestic products | C24: =2500000*12 -> 30000000 | D24: =C24*(1+$D$3) -> 30747000 | E24: =D24*(1+$E$3) -> 31607916 | F24: =E24*(1+$F$3) -> 32524546 | G24: =F24*(1+$G$3) -> 33467757 | H24: =G24*(1+$H$3) -> 34438322 | I24: =H24*(1+$I$3) -> 35430490 | J24: =I24*(1+$I$3) -> 36451243 | K24: =J24*(1+$I$3) -> 37501403 | L24: =K24*(1+$I$3) -> 38581819 | M24: =L24*(1+$I$3) -> 39693361 | N24: =M24*(1+$I$3) -> 40836926 | O24: =N24*(1+$I$3) -> 42013438 | P24: =O24*(1+$I$3) -> 43223846 | ... AQ24: =AP24*(1+$I$3) -> 93062171
A25: Entertainment | C25: =850000*12 -> 10200000 | D25: =C25*(1+$D$3) -> 10453980 | E25: =D25*(1+$E$3) -> 10746691 | F25: =E25*(1+$F$3) -> 11058345 | G25: =F25*(1+$G$3) -> 11379038 | H25: =G25*(1+$H$3) -> 11709030 | I25: =H25*(1+$I$3) -> 12046367 | J25: =I25*(1+$I$3) -> 12393423 | K25: =J25*(1+$I$3) -> 12750477 | L25: =K25*(1+$I$3) -> 13117818 | M25: =L25*(1+$I$3) -> 13495743 | N25: =M25*(1+$I$3) -> 13884555 | O25: =N25*(1+$I$3) -> 14284569 | P25: =O25*(1+$I$3) -> 14696107 | ... AQ25: =AP25*(1+$I$3) -> 31641138
A26: Shopping | C26: =2000000*12 -> 24000000 | D26: =C26*(1+$D$3) -> 24597600 | E26: =D26*(1+$E$3) -> 25286333 | F26: =E26*(1+$F$3) -> 26019636 | G26: =F26*(1+$G$3) -> 26774206 | H26: =G26*(1+$H$3) -> 27550658 | I26: =H26*(1+$I$3) -> 28344392 | J26: =I26*(1+$I$3) -> 29160994 | K26: =J26*(1+$I$3) -> 30001123 | L26: =K26*(1+$I$3) -> 30865455 | M26: =L26*(1+$I$3) -> 31754689 | N26: =M26*(1+$I$3) -> 32669541 | O26: =N26*(1+$I$3) -> 33610751 | P26: =O26*(1+$I$3) -> 34579076 | ... AQ26: =AP26*(1+$I$3) -> 74449737
A27: Maternity cost | H27: 10000000
A28: Living expense for child | H28: ='9. Child living expense'!$E$3 -> 58000000 | I28: ='9. Child living expense'!$E$4*(1+I3) -> 82304800 | J28: =I28*(1+J3) -> 84676001 | K28: ='9. Child living expense'!E5*(1+K3) -> 59670980 | L28: =K28*(1+L3) -> 61390101 | M28: =L28*(1+M3) -> 63158750 | N28: ='9. Child living expense'!E6*(1+N3) -> 27777870 | O28: =N28*(1+O3) -> 28578150 | P28: =O28*(1+P3) -> 29401487 | Q28: =P28*(1+Q3) -> 30248544 | R28: =Q28*(1+R3) -> 31120004 | S28: ='9. Child living expense'!E7*(1+S3) -> 46296450 | T28: =S28*(1+T3) -> 47630251 | U28: =T28*(1+U3) -> 49002478 | V28: =U28*(1+V3) -> 50414240 | W28: ='9. Child living expense'!E8*(1+W3) -> 55555740 | X28: =W28*(1+X3) -> 57156301 | Y28: =X28*(1+Y3) -> 58802974 | Z28: ='9. Child living expense'!E9*(1+Z3) -> 128601250 | AA28: =Z28*(1+AA3) -> 1.3230625e+08 | AB28: =AA28*(1+AB3) -> 1.36118e+08 | AC28: =AB28*(1+AC3) -> 1.4003955e+08 | AD28: =AC28*(1+AD3) -> 1.4407409e+08
A29: Derivative expense such as wedding, funeral | C29: =400000*12 -> 4800000 | D29: =C29*(1+$D$3) -> 4919520 | E29: =D29*(1+$E$3) -> 5057266.6 | F29: =E29*(1+$F$3) -> 5203927.3 | G29: =F29*(1+$G$3) -> 5354841.2 | H29: =G29*(1+$H$3) -> 5510131.6 | I29: =H29*(1+$I$3) -> 5668878.5 | J29: =I29*(1+J3) -> 5832198.9 | K29: =J29*(1+K3) -> 6000224.5 | L29: =K29*(1+L3) -> 6173091 | M29: =L29*(1+M3) -> 6350937.7 | N29: =M29*(1+N3) -> 6533908.2 | O29: =N29*(1+O3) -> 6722150.1 | P29: =O29*(1+P3) -> 6915815.3 | Q29: =P29*(1+Q3) -> 7115059.9 | ... AQ29: =AP29*(1+AQ3) -> 14889947
A30: Healthcare visit | C30: =1000000*12 -> 12000000 | D30: =C30*(1+$D$3) -> 12298800 | E30: =D30*(1+$E$3) -> 12643166 | F30: =E30*(1+$F$3) -> 13009818 | G30: =F30*(1+$G$3) -> 13387103 | H30: =G30*(1+$H$3) -> 13775329 | I30: =H30*(1+$I$3) -> 14172196 | J30: =I30*(1+$I$3) -> 14580497 | K30: =J30*(1+$I$3) -> 15000561 | L30: =K30*(1+$I$3) -> 15432727 | M30: =L30*(1+$I$3) -> 15877344 | N30: =M30*(1+$I$3) -> 16334771 | O30: =N30*(1+$I$3) -> 16805375 | P30: =O30*(1+$I$3) -> 17289538 | ... AQ30: =AP30*(1+$I$3) -> 37224868
